Workbook

Sheet Poengsatt
A1: FASIT | G1: Summerer alle | H1: 7 | I1: 7 | J1: 16 | K1: 15+ | L1: Ghana | M1: Ghana, Annen | N1: Bosnia-Hercegovina | O1: Bosnia-Hercegovina | P1: Tyrikia | Q1: Tyrkia, Tyrikia | R1: 2 | S1: 2 | T1: 6 | U1: 6+ | V1: 215 | W1: 201-250, 215 | X1: 1 - Panama | Y1: 1, 1 - Panama | Z1: 12 | AA1: Flere enn 2, 12 | AB1: 4 | AC1: 4 | AD1: 4 | AE1: 4 | AF1: 3 | AG1: 3 | AH1: 3 | AI1: 3 | AJ1: 1 | AK1: 1 | AL1: 2 | AM1: 2 | AO1: Ikke avgjort | AQ1: Ikke avgjort | AS1: Ikke avgjort | AU1: Ikke avgjort | AV1: Australia og Japan | AW1: Australia, Japan, Australia og Japan | AY1: Ikke avgjort | BA1: Ikke avgjort | BC1: Ikke avgjort | BE1: Ikke avgjort | BG1: Ikke avgjort | BI1: Ikke avgjort | BK1: Ikke avgjort | BL1: Nei | BM1: Nei | BO1: Ikke avgjort | BQ1: Ikke avgjort | BS1: Ikke avgjort | BU1: Ikke avgjort | BW1: Ikke avgjort | BY1: Ikke avgjort | CA1: Ikke avgjort | CC1: Ikke avgjort | CE1: Ikke avgjort | CG1: Ikke avgjort | CI1: Ikke avgjort | CK1: Ikke avgjort | CM1: Ikke avgjort | CO1: Ikke avgjort | CQ1: Ikke avgjort | CS1: Ikke avgjort | CT1: 7 eller flere | CU1: 7 eller flere | CW1: Ikke avgjort | CY1: Ikke avgjort | CZ1: 9+ | DA1: 9+ | DC1: Ikke avgjort | DD1: Norge | DE1: Norge | DF1: Norge | DG1: Norge | DH1: Frankrike | DI1: Frankrike | DK1: Ikke avgjort | DL1: Patrick Berg | DM1: Patrick Berg | DO1: Ikke avgjort | DP1: Ja | DQ1: Ja | DR1: Over 37 | DS1: Over 37 | DU1: Ikke avgjort | DW1: Ikke avgjort | DY1: Nei | EA1: Ikke avgjort | EC1: Ikke avgjort | ED1: Haaland | EE1: Haaland | EF1: 5+ | EG1: 5+ | EI1: Ikke avgjort
A2: Id | B2: Starttidspunkt | C2: Fullføringstidspunkt | D2: E-postadresse | E2: Navn | F2: Navn1 | G2: Poeng totalt | H2: Flest mål sluppet inn i en kamp (gruppespill) | I2: Poeng | J2: Antall kamper med mer enn 4,5 mål i gruppespillet | K2: Poeng | L2: Hvilket lavest rangerte lag vinner en kamp? | M2: Poeng | N2: Lavest UEFA-rankede lag til å gå videre fra gruppespillet | O2: Poeng | P2: Høyest UEFA-rankede lag til å bli slått ut i gruppespillet | Q2: Poeng | R2: Norges plassering i gruppespillet | S2: Poeng | T2: Hvor mange poeng tar Norge i gruppespillet? | U2: Poeng | V2: Totalt antall mål i gruppespillet | W2: Poeng | X2: Hvor mange lag ender gruppespillet med null scorede mål? | Y2: Poeng | Z2: Antall selvmål i gruppespillet | AA2: Poeng | AB2: Topplag gruppe A-D: Hvor mange av disse vinner gruppen sin: Mexico, Sveits, Brasil, USA? | AC2: Poeng | AD2: Topplag gruppe A-D: Hvor mange av disse vinner gruppen sin: Tyskland, Nederland, Belgia, Spania? | AE2: Poeng | AF2: Topplag gruppe A-D: Hvor mange av disse vinner gruppen sin: Frankrike, Argentina, Portugal, England? | AG2: Poeng | AH2: Underdogs, gruppe A-D: Hvor mange går videre av Sør-Afrika, Bosnia-Hercegovina, Haiti, Paraguay? | AI2: Poeng | AJ2: Underdogs, gruppe E-H: Hvor mange går videre av Curaçao, Tunisia, New Zealand, Kapp Verde? | AK2: Poeng | AL2: Underdogs, gruppe I-L: Hvor mange går videre av Irak, Jordan, DR Kongo, Ghana? | AM2: Poeng | AN2: Beste Vertsnasjon? | AO2: Poeng | AP2: Hvilket europeisk lag kommer lengst i VM? | AQ2: Poeng | AR2: Hvilket afrikansk lag kommer lengst i VM? | AS2: Poeng | AT2: Hvilket amerikansk lag kommer lengst i VM? (nord+sør, men utenom vertslandene!) | AU2: Poeng | AV2: Hvilket asiatisk lag kommer lengst i VM? (Inkludert oseania) | AW2: Poeng | AX2: Største målforskjell i en sluttspillskamp? | AY2: Poeng | AZ2: Havner England i en straffekonkurranse? | BA2: Poeng | BB2: Antall kamper som står 0-0 ved full tid i sluttspillet? | BC2: Poeng | BD2: Antall straffekonkurranser i VM? | BE2: Poeng | BF2: Kommer minst én av Spania og Brasil til semifinale? | BG2: Poeng | BH2: Kommer minst én av Frankrike og Argentina til semifinale? | BI2: Poeng | BJ2: Kommer minst én av England og Portugal til semifinale? | BK2: Poeng | BL2: Kommer minst én av Tyskland og Nederland til semifinale? | BM2: Poeng | BN2: Hvem blir toppscorer? | BO2: Poeng | BP2: Hvem får flest assists? | BQ2: Poeng | BR2: Hvem blir beste keeper? | BS2: Poeng | BT2: Hvem blir beste unge spiller? | BU2: Poeng | BV2: Hvilken av spiller får flest kort? | BW2: Poeng | BX2: Totalt antall mål i VM | BY2: Poeng | BZ2: Hvilket lag scorer flest mål i turneringen? | CA2: Poeng | CB2: Hvilket lag holder flest clean sheets (fulltid)? | CC2: Poeng | CD2: Hvem vinner VM? | CE2: Poeng | CF2: Hvem får flest spilleminutter av Messi og Ronaldo? | CG2: Poeng | CH2: Blir Norge involvert i straffesparkkonkurranse? | CI2: Poeng | CJ2: Antall mål toppscoreren ender på | CK2: Poeng | CL2: Totalt antall direkte røde kort | CM2: Poeng | CN2: Totalt antall gule kort over/under 200? | CO2: Poeng | CP2: Totalt antall straffer dømt | CQ2: Poeng | CR2: Totalt antall straffesparkkonkurranser | CS2: Poeng | CT2: Antall selvmål i løpet av VM? | CU2: Poeng | CV2: Største antall gule kort i én kamp? Over/under 11,5 | CW2: Poeng | CX2: Hvem blir toppscorer blant spillere som er 21 år eller yngre ved turneringsstart? | CY2: Poeng | CZ2: Hvor mange mål scorer Norge totalt? | DA2: Poeng | DB2: Hvor mange mål slipper Norge inn totalt? | DC2: Poeng | DD2: Vinner Norge-Irak? | DE2: Poeng | DF2: Vinner Norge-Senegal? | DG2: Poeng | DH2: Vinner Norge-Frankrike? | DI2: Poeng | DJ2: Norges plassering i VM Skriv inn svar | DK2: Poeng | DL2: Hvem får Norges første gule kort? | DM2: Poeng | DN2: Får Norge rødt kort i løpet av VM? | DO2: Poeng | DP2: Blir minst én kamp avbrutt midlertidig på grunn av vær? | DQ2: Poeng | DR2: Høyeste offisielle temperatur ved kampstart | DS2: Poeng | DT2: Hvor langt kommer Norge? | DU2: Poeng | DV2: Hvor mange gule kort får Ryerson? | DW2: Poeng | DX2: Starter Ødegaard alle kampene? | DY2: Poeng | DZ2: Hvor mange kamper får Thelo Aasgaard spille? | EA2: Poeng | EB2: Får Solbakken gult kort? | EC2: Poeng | ED2: Hvem scorer Norges første mål? | EE2: Poeng | EF2: Hvor mange mål scorer Haaland totalt? | EG2: Poeng | EH2: Lengste distanse løpt i finalen av en spiller. | EI2: Poeng
A3: 1 | B3: 46183.286 | C3: 46183.299 | D3: anonymous | F3: Mads Conradi | G3: =SUM(I3:EI3) -> 11 | H3: 6 | I3: =IF(OR(LOWER(TRIM(H3&""))="7"),1,0) -> 0 | J3: 0–6 | K3: =IF(OR(LOWER(TRIM(J3&""))="15+"),1,0) -> 0 | L3: Sør-Afrika | M3: =IF(OR(LOWER(TRIM(L3&""))="ghana",LOWER(TRIM(L3&""))="annen"),1,0) -> 0 | N3: Ghana | O3: =IF(OR(LOWER(TRIM(N3&""))="bosnia-hercegovina"),1,0) -> 0 | P3: Annen | Q3: =IF(OR(LOWER(TRIM(P3&""))="tyrkia",LOWER(TRIM(P3&""))="tyrikia"),1,0) -> 0 | R3: 2 | S3: =IF(OR(LOWER(TRIM(R3&""))="2"),1,0) -> 1 | T3: 6+ | U3: =IF(OR(LOWER(TRIM(T3&""))="6+"),1,0) -> 1 | V3: 51-100 | W3: =IF(OR(LOWER(TRIM(V3&""))="201-250",LOWER(TRIM(V3&""))="215"),1,0) -> 0 | X3: 2 | Y3: =IF(OR(LOWER(TRIM(X3&""))="1",LOWER(TRIM(X3&""))="1 - panama"),1,0) -> 0 | Z3: Flere enn 2 | AA3: =IF(OR(LOWER(TRIM(Z3&""))="flere enn 2",LOWER(TRIM(Z3&""))="12"),1,0) -> 1 | AB3: 1 | AC3: =IF(OR(LOWER(TRIM(AB3&""))="4"),1,0) -> 0 | AD3: 4 | AE3: =IF(OR(LOWER(TRIM(AD3&""))="4"),1,0) -> 1 | AF3: 3 | AG3: =IF(OR(LOWER(TRIM(AF3&""))="3"),1,0) -> 1 | AH3: 1 | AI3: =IF(OR(LOWER(TRIM(AH3&""))="3"),1,0) -> 0 | AJ3: 1 | AK3: =IF(OR(LOWER(TRIM(AJ3&""))="1"),1,0) -> 1 | AL3: 1 | AM3: =IF(OR(LOWER(TRIM(AL3&""))="2"),1,0) -> 0 | AN3: Mexico | AP3: England | AR3: Senegal | AT3: Brasil | AV3: Sør-Korea | AW3: =IF(OR(LOWER(TRIM(AV3&""))="australia",LOWER(TRIM(AV3&""))="japan",LOWER(TRIM(AV3&""))="australia og japan"),1,0) -> 0 | AX3: 1-3 | AZ3: Ja | BB3: 4 | BD3: Flere enn 5 | BF3: Ja | BH3: Ja | BJ3: Ja | BL3: Ja | BM3: =IF(OR(LOWER(TRIM(BL3&""))="nei"),1,0) -> 0 | BN3: Harry Kane | BP3: Michael Olise | BR3: Manuel Neuer | BT3: Nico Paz | BV3: Cristian Romero | BX3: 251-300 | BZ3: Spania | CB3: England | CD3: England | CF3: Messi | CH3: Ja | CJ3: 7 | CL3: 0-3 | CN3: 300 eller flere | CP3: 31-40 | CR3: 5 eller flere | CT3: 0-4. 5-6 | CU3: =IF(OR(LOWER(TRIM(CT3&""))="7 eller flere"),1,0) -> 0 | CV3: Over | CX3: Nico Paz | CZ3: 9+ | DA3: =IF(OR(LOWER(TRIM(CZ3&""))="9+"),1,0) -> 1 | DB3: 3–4 | DD3: Norge | DE3: =IF(OR(LOWER(TRIM(DD3&""))="norge"),1,0) -> 1 | DF3: Norge | DG3: =IF(OR(LOWER(TRIM(DF3&""))="norge"),1,0) -> 1 | DH3: uavgjort | DI3: =IF(OR(LOWER(TRIM(DH3&""))="frankrike"),1,0) -> 0 | DJ3: 8 | DL3: Martin Ødegaard | DM3: =IF(OR(LOWER(TRIM(DL3&""))="patrick berg"),1,0) -> 0 | DN3: Ja | DP3: Nei | DQ3: =IF(OR(LOWER(TRIM(DP3&""))="ja"),1,0) -> 0 | DR3: 35-37 | DS3: =IF(OR(LOWER(TRIM(DR3&""))="over 37"),1,0) -> 0 | DT3: 8. delsfinale | DV3: 2 | DX3: Nei | DY3: 1 | DZ3: 2 | EB3: Nei | ED3: Haaland | EE3: =IF(OR(LOWER(TRIM(ED3&""))="haaland"),1,0) -> 1 | EF3: 4 | EG3: =IF(OR(LOWER(TRIM(EF3&""))="5+"),1,0) -> 0 | EH3: 12,3
A4: 2 | B4: 46183.439 | C4: 46183.449 | D4: anonymous | F4: Jonas Hagen | G4: =SUM(I4:EI4) -> 7 | H4: 10+ | I4: =IF(OR(LOWER(TRIM(H4&""))="7"),1,0) -> 0 | J4: 7–9 | K4: =IF(OR(LOWER(TRIM(J4&""))="15+"),1,0) -> 0 | L4: Irak | M4: =IF(OR(LOWER(TRIM(L4&""))="ghana",LOWER(TRIM(L4&""))="annen"),1,0) -> 0 | N4: Sør-Afrika | O4: =IF(OR(LOWER(TRIM(N4&""))="bosnia-hercegovina"),1,0) -> 0 | P4: Tyskland | Q4: =IF(OR(LOWER(TRIM(P4&""))="tyrkia",LOWER(TRIM(P4&""))="tyrikia"),1,0) -> 0 | R4: 2 | S4: =IF(OR(LOWER(TRIM(R4&""))="2"),1,0) -> 1 | T4: 5 | U4: =IF(OR(LOWER(TRIM(T4&""))="6+"),1,0) -> 0 | V4: 51-100 | W4: =IF(OR(LOWER(TRIM(V4&""))="201-250",LOWER(TRIM(V4&""))="215"),1,0) -> 0 | X4: 2 | Y4: =IF(OR(LOWER(TRIM(X4&""))="1",LOWER(TRIM(X4&""))="1 - panama"),1,0) -> 0 | Z4: 2 | AA4: =IF(OR(LOWER(TRIM(Z4&""))="flere enn 2",LOWER(TRIM(Z4&""))="12"),1,0) -> 0 | AB4: 2 | AC4: =IF(OR(LOWER(TRIM(AB4&""))="4"),1,0) -> 0 | AD4: 2 | AE4: =IF(OR(LOWER(TRIM(AD4&""))="4"),1,0) -> 0 | AF4: 2 | AG4: =IF(OR(LOWER(TRIM(AF4&""))="3"),1,0) -> 0 | AH4: 2 | AI4: =IF(OR(LOWER(TRIM(AH4&""))="3"),1,0) -> 0 | AJ4: 1 | AK4: =IF(OR(LOWER(TRIM(AJ4&""))="1"),1,0) -> 1 | AL4: 2 | AM4: =IF(OR(LOWER(TRIM(AL4&""))="2"),1,0) -> 1 | AN4: Canada | AP4: Norge | AR4: Marokko | AT4: Brasil | AV4: Japan | AW4: =IF(OR(LOWER(TRIM(AV4&""))="australia",LOWER(TRIM(AV4&""))="japan",LOWER(TRIM(AV4&""))="australia og japan"),1,0) -> 1 | AX4: 5 | AZ4: Ja | BB4: 2 | BD4: 4 | BF4: Ja | BH4: Ja | BJ4: Nei | BL4: Nei | BM4: =IF(OR(LOWER(TRIM(BL4&""))="nei"),1,0) -> 1 | BN4: Kylian Mbappé | BP4: Bruno Fernandes | BR4: Emiliano Martínez | BT4: Lamine Yamal | BV4: João Palhinha | BX4: 150-200 | BZ4: Frankrike | CB4: Brasil | CD4: Brasil | CF4: Messi | CH4: Ja | CJ4: 10 | CL4: 0-3 | CN4: Under 200 | CP4: 11-20 | CR4: 4 | CT4: 5-6 | CU4: =IF(OR(LOWER(TRIM(CT4&""))="7 eller flere"),1,0) -> 0 | CV4: Under | CX4: Désiré Doué | CZ4: 7–8 | DA4: =IF(OR(LOWER(TRIM(CZ4&""))="9+"),1,0) -> 0 | DB4: 3–4 | DD4: Norge | DE4: =IF(OR(LOWER(TRIM(DD4&""))="norge"),1,0) -> 1 | DF4: Norge | DG4: =IF(OR(LOWER(TRIM(DF4&""))="norge"),1,0) -> 1 | DH4: uavgjort | DI4: =IF(OR(LOWER(TRIM(DH4&""))="frankrike"),1,0) -> 0 | DJ4: Kvartfinale | DL4: Kristoffer Ajer | DM4: =IF(OR(LOWER(TRIM(DL4&""))="patrick berg"),1,0) -> 0 | DN4: Nei | DP4: Nei | DQ4: =IF(OR(LOWER(TRIM(DP4&""))="ja"),1,0) -> 0 | DR4: 33-35 | DS4: =IF(OR(LOWER(TRIM(DR4&""))="over 37"),1,0) -> 0 | DT4: Kvartfinale | DV4: 2 | DX4: Ja | DY4: 0 | DZ4: 2 | EB4: Ja | ED4: Nusa | EE4: =IF(OR(LOWER(TRIM(ED4&""))="haaland"),1,0) -> 0 | EF4: 3 | EG4: =IF(OR(LOWER(TRIM(EF4&""))="5+"),1,0) -> 0 | EH4: 14-16km
A5: 3 | B5: 46183.439 | C5: 46183.45 | D5: anonymous | F5: Jarle | G5: =SUM(I5:EI5) -> 10 | H5: 6 | I5: =IF(OR(LOWER(TRIM(H5&""))="7"),1,0) -> 0 | J5: 0–6 | K5: =IF(OR(LOWER(TRIM(J5&""))="15+"),1,0) -> 0 | L5: Curaçao | M5: =IF(OR(LOWER(TRIM(L5&""))="ghana",LOWER(TRIM(L5&""))="annen"),1,0) -> 0 | N5: Tunisia | O5: =IF(OR(LOWER(TRIM(N5&""))="bosnia-hercegovina"),1,0) -> 0 | P5: Østerrike | Q5: =IF(OR(LOWER(TRIM(P5&""))="tyrkia",LOWER(TRIM(P5&""))="tyrikia"),1,0) -> 0 | R5: 2 | S5: =IF(OR(LOWER(TRIM(R5&""))="2"),1,0) -> 1 | T5: 6+ | U5: =IF(OR(LOWER(TRIM(T5&""))="6+"),1,0) -> 1 | V5: 151-200 | W5: =IF(OR(LOWER(TRIM(V5&""))="201-250",LOWER(TRIM(V5&""))="215"),1,0) -> 0 | X5: 3 | Y5: =IF(OR(LOWER(TRIM(X5&""))="1",LOWER(TRIM(X5&""))="1 - panama"),1,0) -> 0 | Z5: Flere enn 2 | AA5: =IF(OR(LOWER(TRIM(Z5&""))="flere enn 2",LOWER(TRIM(Z5&""))="12"),1,0) -> 1 | AB5: 2 | AC5: =IF(OR(LOWER(TRIM(AB5&""))="4"),1,0) -> 0 | AD5: 2 | AE5: =IF(OR(LOWER(TRIM(AD5&""))="4"),1,0) -> 0 | AF5: 3 | AG5: =IF(OR(LOWER(TRIM(AF5&""))="3"),1,0) -> 1 | AH5: 1 | AI5: =IF(OR(LOWER(TRIM(AH5&""))="3"),1,0) -> 0 | AJ5: 2 | AK5: =IF(OR(LOWER(TRIM(AJ5&""))="1"),1,0) -> 0 | AL5: 0 | AM5: =IF(OR(LOWER(TRIM(AL5&""))="2"),1,0) -> 0 | AN5: Mexico | AP5: Spania | AR5: Marokko | AT5: Brasil | AV5: Japan | AW5: =IF(OR(LOWER(TRIM(AV5&""))="australia",LOWER(TRIM(AV5&""))="japan",LOWER(TRIM(AV5&""))="australia og japan"),1,0) -> 1 | AX5: 4 | AZ5: Ja | BB5: 3 | BD5: 4 | BF5: Ja | BH5: Ja | BJ5: Nei | BL5: Ja | BM5: =IF(OR(LOWER(TRIM(BL5&""))="nei"),1,0) -> 0 | BN5: Kylian Mbappé | BP5: Annen | BR5: Manuel Neuer | BT5: Lamine Yamal | BV5: Annen | BX5: 201-250 | BZ5: Frankrike | CB5: Portugal | CD5: Frankrike | CF5: Messi | CH5: Ja | CJ5: 9 | CL5: 4-5 | CN5: Under 200 | CP5: 11-20 | CR5: 5 eller flere | CT5: 5-6 | CU5: =IF(OR(LOWER(TRIM(CT5&""))="7 eller flere"),1,0) -> 0 | CV5: Under | CX5: Lamine Yamal | CZ5: 3–4 | DA5: =IF(OR(LOWER(TRIM(CZ5&""))="9+"),1,0) -> 0 | DB5: 5–6 | DD5: Norge | DE5: =IF(OR(LOWER(TRIM(DD5&""))="norge"),1,0) -> 1 | DF5: Norge | DG5: =IF(OR(LOWER(TRIM(DF5&""))="norge"),1,0) -> 1 | DH5: Frankrike | DI5: =IF(OR(LOWER(TRIM(DH5&""))="frankrike"),1,0) -> 1 | DJ5: 12 | DL5: Julian Ryerson | DM5: =IF(OR(LOWER(TRIM(DL5&""))="patrick berg"),1,0) -> 0 | DN5: Nei | DP5: Ja | DQ5: =IF(OR(LOWER(TRIM(DP5&""))="ja"),1,0) -> 1 | DR5: 33-35 | DS5: =IF(OR(LOWER(TRIM(DR5&""))="over 37"),1,0) -> 0 | DT5: 8. delsfinale | DV5: Flere enn 2 | DX5: Ja | DY5: 0 | DZ5: 2 | EB5: Nei | ED5: Haaland | EE5: =IF(OR(LOWER(TRIM(ED5&""))="haaland"),1,0) -> 1 | EF5: 2 | EG5: =IF(OR(LOWER(TRIM(EF5&""))="5+"),1,0) -> 0 | EH5: 11,2 km
A6: 4 | B6: 46183.436 | C6: 46183.46 | D6: anonymous | F6: El Jefe | G6: =SUM(I6:EI6) -> 14 | H6: 6 | I6: =IF(OR(LOWER(TRIM(H6&""))="7"),1,0) -> 0 | J6: 7–9 | K6: =IF(OR(LOWER(TRIM(J6&""))="15+"),1,0) -> 0 | L6: DR Kongo | M6: =IF(OR(LOWER(TRIM(L6&""))="ghana",LOWER(TRIM(L6&""))="annen"),1,0) -> 0 | N6: Bosnia-Hercegovina | O6: =IF(OR(LOWER(TRIM(N6&""))="bosnia-hercegovina"),1,0) -> 1 | P6: Østerrike | Q6: =IF(OR(LOWER(TRIM(P6&""))="tyrkia",LOWER(TRIM(P6&""))="tyrikia"),1,0) -> 0 | R6: 2 | S6: =IF(OR(LOWER(TRIM(R6&""))="2"),1,0) -> 1 | T6: 5 | U6: =IF(OR(LOWER(TRIM(T6&""))="6+"),1,0) -> 0 | V6: 151-200 | W6: =IF(OR(LOWER(TRIM(V6&""))="201-250",LOWER(TRIM(V6&""))="215"),1,0) -> 0 | X6: 1 | Y6: =IF(OR(LOWER(TRIM(X6&""))="1",LOWER(TRIM(X6&""))="1 - panama"),1,0) -> 1 | Z6: Flere enn 2 | AA6: =IF(OR(LOWER(TRIM(Z6&""))="flere enn 2",LOWER(TRIM(Z6&""))="12"),1,0) -> 1 | AB6: 2 | AC6: =IF(OR(LOWER(TRIM(AB6&""))="4"),1,0) -> 0 | AD6: 4 | AE6: =IF(OR(LOWER(TRIM(AD6&""))="4"),1,0) -> 1 | AF6: 3 | AG6: =IF(OR(LOWER(TRIM(AF6&""))="3"),1,0) -> 1 | AH6: 2 | AI6: =IF(OR(LOWER(TRIM(AH6&""))="3"),1,0) -> 0 | AJ6: 0 | AK6: =IF(OR(LOWER(TRIM(AJ6&""))="1"),1,0) -> 0 | AL6: 1 | AM6: =IF(OR(LOWER(TRIM(AL6&""))="2"),1,0) -> 0 | AN6: Mexico | AP6: Spania | AR6: Egypt | AT6: Argentina | AV6: Japan | AW6: =IF(OR(LOWER(TRIM(AV6&""))="australia",LOWER(TRIM(AV6&""))="japan",LOWER(TRIM(AV6&""))="australia og japan"),1,0) -> 1 | AX6: 4 | AZ6: Ja | BB6: 3 | BD6: Flere enn 5 | BF6: Ja | BH6: Ja | BJ6: Ja | BL6: Ja | BM6: =IF(OR(LOWER(TRIM(BL6&""))="nei"),1,0) -> 0 | BN6: Annen | BP6: Annen | BR6: Annen | BT6: Nico Paz | BV6: Annen | BX6: 251-300 | BZ6: Argentina | CB6: Argentina | CD6: Argentina | CF6: Messi | CH6: Nei | CJ6: 10 | CL6: 8 eller flere | CN6: 300 eller flere | CP6: 31-40 | CR6: 5 eller flere | CT6: 7 eller flere | CU6: =IF(OR(LOWER(TRIM(CT6&""))="7 eller flere"),1,0) -> 1 | CV6: Over | CX6: Endrick | CZ6: 9+ | DA6: =IF(OR(LOWER(TRIM(CZ6&""))="9+"),1,0) -> 1 | DB6: 7–8 | DD6: Norge | DE6: =IF(OR(LOWER(TRIM(DD6&""))="norge"),1,0) -> 1 | DF6: uavgjort | DG6: =IF(OR(LOWER(TRIM(DF6&""))="norge"),1,0) -> 0 | DH6: Frankrike | DI6: =IF(OR(LOWER(TRIM(DH6&""))="frankrike"),1,0) -> 1 | DJ6: 16-dels | DL6: Fredrik Aursnes | DM6: =IF(OR(LOWER(TRIM(DL6&""))="patrick berg"),1,0) -> 0 | DN6: Nei | DP6: Nei | DQ6: =IF(OR(LOWER(TRIM(DP6&""))="ja"),1,0) -> 0 | DR6: Over 37 | DS6: =IF(OR(LOWER(TRIM(DR6&""))="over 37"),1,0) -> 1 | DT6: 16. delsfinale | DV6: 1 | DX6: Ja | DY6: 0 | DZ6: 3 | EB6: Nei | ED6: Haaland | EE6: =IF(OR(LOWER(TRIM(ED6&""))="haaland"),1,0) -> 1 | EF6: 5+ | EG6: =IF(OR(LOWER(TRIM(EF6&""))="5+"),1,0) -> 1 | EH6: 12,6 km
A7: 5 | B7: 46183.459 | C7: 46183.486 | D7: anonymous | F7: Joachim E-H | G7: =SUM(I7:EI7) -> 10 | H7: 10+ | I7: =IF(OR(LOWER(TRIM(H7&""))="7"),1,0) -> 0 | J7: 7–9 | K7: =IF(OR(LOWER(TRIM(J7&""))="15+"),1,0) -> 0 | L7: Sør-Afrika | M7: =IF(OR(LOWER(TRIM(L7&""))="ghana",LOWER(TRIM(L7&""))="annen"),1,0) -> 0 | N7: Ghana | O7: =IF(OR(LOWER(TRIM(N7&""))="bosnia-hercegovina"),1,0) -> 0 | P7: Kroatia | Q7: =IF(OR(LOWER(TRIM(P7&""))="tyrkia",LOWER(TRIM(P7&""))="tyrikia"),1,0) -> 0 | R7: 2 | S7: =IF(OR(LOWER(TRIM(R7&""))="2"),1,0) -> 1 | T7: 6+ | U7: =IF(OR(LOWER(TRIM(T7&""))="6+"),1,0) -> 1 | V7: 151-200 | W7: =IF(OR(LOWER(TRIM(V7&""))="201-250",LOWER(TRIM(V7&""))="215"),1,0) -> 0 | X7: 2 | Y7: =IF(OR(LOWER(TRIM(X7&""))="1",LOWER(TRIM(X7&""))="1 - panama"),1,0) -> 0 | Z7: 2 | AA7: =IF(OR(LOWER(TRIM(Z7&""))="flere enn 2",LOWER(TRIM(Z7&""))="12"),1,0) -> 0 | AB7: 1 | AC7: =IF(OR(LOWER(TRIM(AB7&""))="4"),1,0) -> 0 | AD7: 2 | AE7: =IF(OR(LOWER(TRIM(AD7&""))="4"),1,0) -> 0 | AF7: 3 | AG7: =IF(OR(LOWER(TRIM(AF7&""))="3"),1,0) -> 1 | AH7: 0 | AI7: =IF(OR(LOWER(TRIM(AH7&""))="3"),1,0) -> 0 | AJ7: 0 | AK7: =IF(OR(LOWER(TRIM(AJ7&""))="1"),1,0) -> 0 | AL7: 1 | AM7: =IF(OR(LOWER(TRIM(AL7&""))="2"),1,0) -> 0 | AN7: Mexico | AP7: Frankrike | AR7: Marokko | AT7: Argentina | AV7: Japan | AW7: =IF(OR(LOWER(TRIM(AV7&""))="australia",LOWER(TRIM(AV7&""))="japan",LOWER(TRIM(AV7&""))="australia og japan"),1,0) -> 1 | AX7: 4 | AZ7: Ja | BB7: 2 | BD7: 3 | BF7: Ja | BH7: Ja | BJ7: Ja | BL7: Nei | BM7: =IF(OR(LOWER(TRIM(BL7&""))="nei"),1,0) -> 1 | BN7: Annen | BP7: Bruno Fernandes | BR7: Emiliano Martínez | BT7: Désiré Doué | BV7: Manuel Ugarte | BX7: 251-300 | BZ7: Frankrike | CB7: Tyskland | CD7: Frankrike | CF7: Messi | CH7: Nei | CJ7: 9 | CL7: 4-5 | CN7: Under 200 | CP7: 11-20 | CR7: 3 | CT7: 5-6 | CU7: =IF(OR(LOWER(TRIM(CT7&""))="7 eller flere"),1,0) -> 0 | CV7: Under | CX7: Lamine Yamal | CZ7: 7–8 | DA7: =IF(OR(LOWER(TRIM(CZ7&""))="9+"),1,0) -> 0 | DB7: 3–4 | DD7: Norge | DE7: =IF(OR(LOWER(TRIM(DD7&""))="norge"),1,0) -> 1 | DF7: Norge | DG7: =IF(OR(LOWER(TRIM(DF7&""))="norge"),1,0) -> 1 | DH7: Frankrike | DI7: =IF(OR(LOWER(TRIM(DH7&""))="frankrike"),1,0) -> 1 | DJ7: Åttendelsfinale | DL7: Kristoffer Ajer | DM7: =IF(OR(LOWER(TRIM(DL7&""))="patrick berg"),1,0) -> 0 | DN7: Nei | DP7: Ja | DQ7: =IF(OR(LOWER(TRIM(DP7&""))="ja"),1,0) -> 1 | DR7: 35-37 | DS7: =IF(OR(LOWER(TRIM(DR7&""))="over 37"),1,0) -> 0 | DT7: 8. delsfinale | DV7: 1 | DX7: Ja | DY7: 0 | DZ7: 1 | EB7: Nei | ED7: Haaland | EE7: =IF(OR(LOWER(TRIM(ED7&""))="haaland"),1,0) -> 1 | EF7: 3 | EG7: =IF(OR(LOWER(TRIM(EF7&""))="5+"),1,0) -> 0 | EH7: 8 kilometer
A8: 6 | B8: 46183.496 | C8: 46183.503 | D8: anonymous | F8: Njord Are | G8: =SUM(I8:EI8) -> 12 | H8: 6 | I8: =IF(OR(LOWER(TRIM(H8&""))="7"),1,0) -> 0 | J8: 7–9 | K8: =IF(OR(LOWER(TRIM(J8&""))="15+"),1,0) -> 0 | L8: Sør-Afrika | M8: =IF(OR(LOWER(TRIM(L8&""))="ghana",LOWER(TRIM(L8&""))="annen"),1,0) -> 0 | N8: Ghana | O8: =IF(OR(LOWER(TRIM(N8&""))="bosnia-hercegovina"),1,0) -> 0 | P8: Belgia | Q8: =IF(OR(LOWER(TRIM(P8&""))="tyrkia",LOWER(TRIM(P8&""))="tyrikia"),1,0) -> 0 | R8: 2 | S8: =IF(OR(LOWER(TRIM(R8&""))="2"),1,0) -> 1 | T8: 6+ | U8: =IF(OR(LOWER(TRIM(T8&""))="6+"),1,0) -> 1 | V8: 151-200 | W8: =IF(OR(LOWER(TRIM(V8&""))="201-250",LOWER(TRIM(V8&""))="215"),1,0) -> 0 | X8: 2 | Y8: =IF(OR(LOWER(TRIM(X8&""))="1",LOWER(TRIM(X8&""))="1 - panama"),1,0) -> 0 | Z8: 2 | AA8: =IF(OR(LOWER(TRIM(Z8&""))="flere enn 2",LOWER(TRIM(Z8&""))="12"),1,0) -> 0 | AB8: 1 | AC8: =IF(OR(LOWER(TRIM(AB8&""))="4"),1,0) -> 0 | AD8: 3 | AE8: =IF(OR(LOWER(TRIM(AD8&""))="4"),1,0) -> 0 | AF8: 4 | AG8: =IF(OR(LOWER(TRIM(AF8&""))="3"),1,0) -> 0 | AH8: 2 | AI8: =IF(OR(LOWER(TRIM(AH8&""))="3"),1,0) -> 0 | AJ8: 1 | AK8: =IF(OR(LOWER(TRIM(AJ8&""))="1"),1,0) -> 1 | AL8: 1 | AM8: =IF(OR(LOWER(TRIM(AL8&""))="2"),1,0) -> 0 | AN8: USA | AP8: Spania | AR8: Marokko | AT8: Argentina | AV8: Japan | AW8: =IF(OR(LOWER(TRIM(AV8&""))="australia",LOWER(TRIM(AV8&""))="japan",LOWER(TRIM(AV8&""))="australia og japan"),1,0) -> 1 | AX8: 4 | AZ8: Ja | BB8: 1 | BD8: 3 | BF8: Ja | BH8: Ja | BJ8: Ja | BL8: Nei | BM8: =IF(OR(LOWER(TRIM(BL8&""))="nei"),1,0) -> 1 | BN8: Lionel Messi | BP8: Lionel Messi | BR8: Manuel Neuer | BT8: Lamine Yamal | BV8: Rodrigo De Paul | BX8: 201-250 | BZ8: Frankrike | CB8: Spania | CD8: Spania | CF8: Messi | CH8: Ja | CJ8: 8 | CL8: 0-3 | CN8: Under 200 | CP8: 0-10 | CR8: 3 | CT8: 0-4 | CU8: =IF(OR(LOWER(TRIM(CT8&""))="7 eller flere"),1,0) -> 0 | CV8: Under | CX8: Lamine Yamal | CZ8: 9+ | DA8: =IF(OR(LOWER(TRIM(CZ8&""))="9+"),1,0) -> 1 | DB8: 5–6 | DD8: Norge | DE8: =IF(OR(LOWER(TRIM(DD8&""))="norge"),1,0) -> 1 | DF8: Norge | DG8: =IF(OR(LOWER(TRIM(DF8&""))="norge"),1,0) -> 1 | DH8: Frankrike | DI8: =IF(OR(LOWER(TRIM(DH8&""))="frankrike"),1,0) -> 1 | DJ8: Kvartfinale | DL8: Julian Ryerson | DM8: =IF(OR(LOWER(TRIM(DL8&""))="patrick berg"),1,0) -> 0 | DN8: Ja | DP8: Ja | DQ8: =IF(OR(LOWER(TRIM(DP8&""))="ja"),1,0) -> 1 | DR8: Over 37 | DS8: =IF(OR(LOWER(TRIM(DR8&""))="over 37"),1,0) -> 1 | DT8: Kvartfinale | DV8: 2 | DX8: Ja | DY8: 0 | DZ8: 1 | EB8: Nei | ED8: Haaland | EE8: =IF(OR(LOWER(TRIM(ED8&""))="haaland"),1,0) -> 1 | EF8: 4 | EG8: =IF(OR(LOWER(TRIM(EF8&""))="5+"),1,0) -> 0 | EH8: 13,7
A9: 7 | B9: 46183.501 | C9: 46183.507 | D9: anonymous | F9: Brændmo | G9: =SUM(I9:EI9) -> 6 | H9: 6 | I9: =IF(OR(LOWER(TRIM(H9&""))="7"),1,0) -> 0 | J9: 7–9 | K9: =IF(OR(LOWER(TRIM(J9&""))="15+"),1,0) -> 0 | L9: Qatar | M9: =IF(OR(LOWER(TRIM(L9&""))="ghana",LOWER(TRIM(L9&""))="annen"),1,0) -> 0 | N9: Paraguay | O9: =IF(OR(LOWER(TRIM(N9&""))="bosnia-hercegovina"),1,0) -> 0 | Q9: =IF(OR(LOWER(TRIM(P9&""))="tyrkia",LOWER(TRIM(P9&""))="tyrikia"),1,0) -> 0 | R9: 2 | S9: =IF(OR(LOWER(TRIM(R9&""))="2"),1,0) -> 1 | T9: 5 | U9: =IF(OR(LOWER(TRIM(T9&""))="6+"),1,0) -> 0 | V9: 51-100 | W9: =IF(OR(LOWER(TRIM(V9&""))="201-250",LOWER(TRIM(V9&""))="215"),1,0) -> 0 | X9: 3 | Y9: =IF(OR(LOWER(TRIM(X9&""))="1",LOWER(TRIM(X9&""))="1 - panama"),1,0) -> 0 | Z9: Flere enn 2 | AA9: =IF(OR(LOWER(TRIM(Z9&""))="flere enn 2",LOWER(TRIM(Z9&""))="12"),1,0) -> 1 | AB9: 1 | AC9: =IF(OR(LOWER(TRIM(AB9&""))="4"),1,0) -> 0 | AD9: 2 | AE9: =IF(OR(LOWER(TRIM(AD9&""))="4"),1,0) -> 0 | AF9: 2 | AG9: =IF(OR(LOWER(TRIM(AF9&""))="3"),1,0) -> 0 | AH9: 1 | AI9: =IF(OR(LOWER(TRIM(AH9&""))="3"),1,0) -> 0 | AJ9: 0 | AK9: =IF(OR(LOWER(TRIM(AJ9&""))="1"),1,0) -> 0 | AL9: 0 | AM9: =IF(OR(LOWER(TRIM(AL9&""))="2"),1,0) -> 0 | AN9: Mexico | AP9: Spania | AR9: Senegal | AT9: Argentina | AV9: Qatar | AW9: =IF(OR(LOWER(TRIM(AV9&""))="australia",LOWER(TRIM(AV9&""))="japan",LOWER(TRIM(AV9&""))="australia og japan"),1,0) -> 0 | AX9: 4 | AZ9: Nei | BB9: 3 | BD9: 4 | BF9: Ja | BH9: Ja | BJ9: Nei | BL9: Ja | BM9: =IF(OR(LOWER(TRIM(BL9&""))="nei"),1,0) -> 0 | BN9: Lionel Messi | BP9: Kylian Mbappé | BR9: Manuel Neuer | BT9: Lamine Yamal | BV9: Cristian Romero | BX9: 201-250 | BZ9: Spania | CB9: Tyskland | CD9: Argentina | CF9: Messi | CH9: Nei | CJ9: 9 | CL9: 0-3 | CN9: Under 200 | CP9: 21-30 | CR9: 4 | CT9: 5-6 | CU9: =IF(OR(LOWER(TRIM(CT9&""))="7 eller flere"),1,0) -> 0 | CV9: Under | CX9: Lamine Yamal | CZ9: 7–8 | DA9: =IF(OR(LOWER(TRIM(CZ9&""))="9+"),1,0) -> 0 | DB9: 5–6 | DD9: Norge | DE9: =IF(OR(LOWER(TRIM(DD9&""))="norge"),1,0) -> 1 | DF9: Senegal | DG9: =IF(OR(LOWER(TRIM(DF9&""))="norge"),1,0) -> 0 | DH9: Frankrike | DI9: =IF(OR(LOWER(TRIM(DH9&""))="frankrike"),1,0) -> 1 | DJ9: 32 | DL9: Leo Østigård | DM9: =IF(OR(LOWER(TRIM(DL9&""))="patrick berg"),1,0) -> 0 | DN9: Nei | DP9: Ja | DQ9: =IF(OR(LOWER(TRIM(DP9&""))="ja"),1,0) -> 1 | DR9: 35-37 | DS9: =IF(OR(LOWER(TRIM(DR9&""))="over 37"),1,0) -> 0 | DT9: 16. delsfinale | DV9: 1 | DX9: Nei | DY9: 1 | DZ9: 2 | EB9: Nei | ED9: Sørloth | EE9: =IF(OR(LOWER(TRIM(ED9&""))="haaland"),1,0) -> 0 | EF9: 4 | EG9: =IF(OR(LOWER(TRIM(EF9&""))="5+"),1,0) -> 0 | EH9: 10,85 km
A10: 8 | B10: 46183.65 | C10: 46183.667 | D10: anonymous | F10: Nichlas André Furu Tunes | G10: =SUM(I10:EI10) -> 9 | H10: 8 | I10: =IF(OR(LOWER(TRIM(H10&""))="7"),1,0) -> 0 | J10: 10–12 | K10: =IF(OR(LOWER(TRIM(J10&""))="15+"),1,0) -> 0 | L10: Qatar | M10: =IF(OR(LOWER(TRIM(L10&""))="ghana",LOWER(TRIM(L10&""))="annen"),1,0) -> 0 | N10: Tunisia | O10: =IF(OR(LOWER(TRIM(N10&""))="bosnia-hercegovina"),1,0) -> 0 | P10: Annen | Q10: =IF(OR(LOWER(TRIM(P10&""))="tyrkia",LOWER(TRIM(P10&""))="tyrikia"),1,0) -> 0 | R10: 2 | S10: =IF(OR(LOWER(TRIM(R10&""))="2"),1,0) -> 1 | T10: 4 | U10: =IF(OR(LOWER(TRIM(T10&""))="6+"),1,0) -> 0 | V10: 101-150 | W10: =IF(OR(LOWER(TRIM(V10&""))="201-250",LOWER(TRIM(V10&""))="215"),1,0) -> 0 | X10: 3 | Y10: =IF(OR(LOWER(TRIM(X10&""))="1",LOWER(TRIM(X10&""))="1 - panama"),1,0) -> 0 | Z10: Flere enn 2 | AA10: =IF(OR(LOWER(TRIM(Z10&""))="flere enn 2",LOWER(TRIM(Z10&""))="12"),1,0) -> 1 | AB10: 3 | AC10: =IF(OR(LOWER(TRIM(AB10&""))="4"),1,0) -> 0 | AD10: 4 | AE10: =IF(OR(LOWER(TRIM(AD10&""))="4"),1,0) -> 1 | AF10: 3 | AG10: =IF(OR(LOWER(TRIM(AF10&""))="3"),1,0) -> 1 | AH10: 1 | AI10: =IF(OR(LOWER(TRIM(AH10&""))="3"),1,0) -> 0 | AJ10: 0 | AK10: =IF(OR(LOWER(TRIM(AJ10&""))="1"),1,0) -> 0 | AL10: 0 | AM10: =IF(OR(LOWER(TRIM(AL10&""))="2"),1,0) -> 0 | AN10: Mexico | AP10: Frankrike | AR10: Senegal | AT10: Brasil | AV10: Japan | AW10: =IF(OR(LOWER(TRIM(AV10&""))="australia",LOWER(TRIM(AV10&""))="japan",LOWER(TRIM(AV10&""))="australia og japan"),1,0) -> 1 | AX10: 4 | AZ10: Ja | BB10: 3 | BD10: 4 | BF10: Ja | BH10: Ja | BJ10: Nei | BL10: Ja | BM10: =IF(OR(LOWER(TRIM(BL10&""))="nei"),1,0) -> 0 | BN10: Harry Kane | BP10: Bruno Fernandes | BR10: Alisson Becker | BT10: Lamine Yamal | BV10: Granit Xhaka | BX10: 251-300 | BZ10: Spania | CB10: Spania | CD10: Frankrike | CF10: Ronaldo | CH10: Nei | CJ10: Over 10 | CL10: 6-7 | CN10: Under 200 | CP10: 31-40 | CR10: 5 eller flere | CT10: 5-6 | CU10: =IF(OR(LOWER(TRIM(CT10&""))="7 eller flere"),1,0) -> 0 | CV10: Under | CX10: Lamine Yamal | CZ10: 7–8 | DA10: =IF(OR(LOWER(TRIM(CZ10&""))="9+"),1,0) -> 0 | DB10: 3–4 | DD10: Norge | DE10: =IF(OR(LOWER(TRIM(DD10&""))="norge"),1,0) -> 1 | DF10: uavgjort | DG10: =IF(OR(LOWER(TRIM(DF10&""))="norge"),1,0) -> 0 | DH10: Frankrike | DI10: =IF(OR(LOWER(TRIM(DH10&""))="frankrike"),1,0) -> 1 | DJ10: 10 | DL10: Julian Ryerson | DM10: =IF(OR(LOWER(TRIM(DL10&""))="patrick berg"),1,0) -> 0 | DN10: Nei | DP10: Ja | DQ10: =IF(OR(LOWER(TRIM(DP10&""))="ja"),1,0) -> 1 | DR10: 35-37 | DS10: =IF(OR(LOWER(TRIM(DR10&""))="over 37"),1,0) -> 0 | DT10: 8. delsfinale | DV10: 2 | DX10: Ja | DY10: 0 | DZ10: 1 | EB10: Ja | ED10: Haaland | EE10: =IF(OR(LOWER(TRIM(ED10&""))="haaland"),1,0) -> 1 | EF10: 4 | EG10: =IF(OR(LOWER(TRIM(EF10&""))="5+"),1,0) -> 0 | EH10: 13
A11: 9 | B11: 46184.392 | C11: 46184.422 | D11: anonymous | F11: Mathias "Smultring" Langaard | G11: =SUM(I11:EI11) -> 14 | H11: 7 | I11: =IF(OR(LOWER(TRIM(H11&""))="7"),1,0) -> 1 | J11: 15+ | K11: =IF(OR(LOWER(TRIM(J11&""))="15+"),1,0) -> 1 | L11: Panama | M11: =IF(OR(LOWER(TRIM(L11&""))="ghana",LOWER(TRIM(L11&""))="annen"),1,0) -> 0 | N11: Ghana | O11: =IF(OR(LOWER(TRIM(N11&""))="bosnia-hercegovina"),1,0) -> 0 | Q11: =IF(OR(LOWER(TRIM(P11&""))="tyrkia",LOWER(TRIM(P11&""))="tyrikia"),1,0) -> 0 | R11: 2 | S11: =IF(OR(LOWER(TRIM(R11&""))="2"),1,0) -> 1 | T11: 6+ | U11: =IF(OR(LOWER(TRIM(T11&""))="6+"),1,0) -> 1 | V11: 151-200 | W11: =IF(OR(LOWER(TRIM(V11&""))="201-250",LOWER(TRIM(V11&""))="215"),1,0) -> 0 | X11: 5 eller flere | Y11: =IF(OR(LOWER(TRIM(X11&""))="1",LOWER(TRIM(X11&""))="1 - panama"),1,0) -> 0 | Z11: 1 | AA11: =IF(OR(LOWER(TRIM(Z11&""))="flere enn 2",LOWER(TRIM(Z11&""))="12"),1,0) -> 0 | AB11: 3 | AC11: =IF(OR(LOWER(TRIM(AB11&""))="4"),1,0) -> 0 | AD11: 3 | AE11: =IF(OR(LOWER(TRIM(AD11&""))="4"),1,0) -> 0 | AF11: 3 | AG11: =IF(OR(LOWER(TRIM(AF11&""))="3"),1,0) -> 1 | AH11: 2 | AI11: =IF(OR(LOWER(TRIM(AH11&""))="3"),1,0) -> 0 | AJ11: 2 | AK11: =IF(OR(LOWER(TRIM(AJ11&""))="1"),1,0) -> 0 | AL11: 2 | AM11: =IF(OR(LOWER(TRIM(AL11&""))="2"),1,0) -> 1 | AN11: Mexico | AP11: Norge | AR11: Marokko | AT11: Argentina | AV11: Australia | AW11: =IF(OR(LOWER(TRIM(AV11&""))="australia",LOWER(TRIM(AV11&""))="japan",LOWER(TRIM(AV11&""))="australia og japan"),1,0) -> 1 | AX11: 4 | AZ11: Ja | BB11: 3 | BD11: 5 | BF11: Ja | BH11: Ja | BJ11: Ja | BL11: Nei | BM11: =IF(OR(LOWER(TRIM(BL11&""))="nei"),1,0) -> 1 | BN11: Erling Haaland | BP11: Bruno Fernandes | BR11: Manuel Neuer | BT11: Lamine Yamal | BV11: Virgil van Dijk | BX11: Over 300 | BZ11: Spania | CB11: Frankrike | CD11: England | CF11: Ronaldo | CH11: Ja | CJ11: Over 10 | CL11: 4-5 | CN11: 201-299 | CP11: 31-40 | CR11: 5 eller flere | CT11: 0-4 | CU11: =IF(OR(LOWER(TRIM(CT11&""))="7 eller flere"),1,0) -> 0 | CV11: Under | CX11: Lamine Yamal | CZ11: 9+ | DA11: =IF(OR(LOWER(TRIM(CZ11&""))="9+"),1,0) -> 1 | DB11: 7–8 | DD11: Norge | DE11: =IF(OR(LOWER(TRIM(DD11&""))="norge"),1,0) -> 1 | DF11: Norge | DG11: =IF(OR(LOWER(TRIM(DF11&""))="norge"),1,0) -> 1 | DH11: Frankrike | DI11: =IF(OR(LOWER(TRIM(DH11&""))="frankrike"),1,0) -> 1 | DJ11: 6 | DL11: Leo Østigård | DM11: =IF(OR(LOWER(TRIM(DL11&""))="patrick berg"),1,0) -> 0 | DN11: Nei | DP11: Ja | DQ11: =IF(OR(LOWER(TRIM(DP11&""))="ja"),1,0) -> 1 | DR11: Over 37 | DS11: =IF(OR(LOWER(TRIM(DR11&""))="over 37"),1,0) -> 1 | DT11: Kvartfinale | DV11: 2 | DX11: Ja | DY11: 0 | DZ11: 2 | EB11: Nei | ED11: Sørloth | EE11: =IF(OR(LOWER(TRIM(ED11&""))="haaland"),1,0) -> 0 | EF11: 4 | EG11: =IF(OR(LOWER(TRIM(EF11&""))="5+"),1,0) -> 0 | EH11: 14750m
A12: 10 | B12: 46184.576 | C12: 46184.582 | D12: anonymous | F12: Dons | G12: =SUM(I12:EI12) -> 6 | H12: 5 | I12: =IF(OR(LOWER(TRIM(H12&""))="7"),1,0) -> 0 | J12: 7–9 | K12: =IF(OR(LOWER(TRIM(J12&""))="15+"),1,0) -> 0 | L12: Sør-Afrika | M12: =IF(OR(LOWER(TRIM(L12&""))="ghana",LOWER(TRIM(L12&""))="annen"),1,0) -> 0 | N12: Tunisia | O12: =IF(OR(LOWER(TRIM(N12&""))="bosnia-hercegovina"),1,0) -> 0 | P12: Kroatia | Q12: =IF(OR(LOWER(TRIM(P12&""))="tyrkia",LOWER(TRIM(P12&""))="tyrikia"),1,0) -> 0 | R12: 3 | S12: =IF(OR(LOWER(TRIM(R12&""))="2"),1,0) -> 0 | T12: 4 | U12: =IF(OR(LOWER(TRIM(T12&""))="6+"),1,0) -> 0 | V12: 101-150 | W12: =IF(OR(LOWER(TRIM(V12&""))="201-250",LOWER(TRIM(V12&""))="215"),1,0) -> 0 | X12: 3 | Y12: =IF(OR(LOWER(TRIM(X12&""))="1",LOWER(TRIM(X12&""))="1 - panama"),1,0) -> 0 | Z12: Flere enn 2 | AA12: =IF(OR(LOWER(TRIM(Z12&""))="flere enn 2",LOWER(TRIM(Z12&""))="12"),1,0) -> 1 | AB12: 2 | AC12: =IF(OR(LOWER(TRIM(AB12&""))="4"),1,0) -> 0 | AD12: 3 | AE12: =IF(OR(LOWER(TRIM(AD12&""))="4"),1,0) -> 0 | AF12: 3 | AG12: =IF(OR(LOWER(TRIM(AF12&""))="3"),1,0) -> 1 | AH12: 1 | AI12: =IF(OR(LOWER(TRIM(AH12&""))="3"),1,0) -> 0 | AJ12: 0 | AK12: =IF(OR(LOWER(TRIM(AJ12&""))="1"),1,0) -> 0 | AL12: 0 | AM12: =IF(OR(LOWER(TRIM(AL12&""))="2"),1,0) -> 0 | AN12: Mexico | AP12: Frankrike | AR12: Marokko | AT12: Brasil | AV12: Sør-Korea | AW12: =IF(OR(LOWER(TRIM(AV12&""))="australia",LOWER(TRIM(AV12&""))="japan",LOWER(TRIM(AV12&""))="australia og japan"),1,0) -> 0 | AX12: 1-3 | AZ12: Nei | BB12: 2 | BD12: 2 | BF12: Ja | BH12: Ja | BJ12: Ja | BL12: Ja | BM12: =IF(OR(LOWER(TRIM(BL12&""))="nei"),1,0) -> 0 | BN12: Harry Kane | BP12: Michael Olise | BR12: Alisson Becker | BT12: Désiré Doué | BV12: Manuel Ugarte | BX12: 201-250 | BZ12: Frankrike | CB12: Tyskland | CD12: Spania | CF12: Messi | CH12: Nei | CJ12: 9 | CL12: 4-5 | CN12: Under 200 | CP12: 31-40 | CR12: 3 | CT12: 5-6 | CU12: =IF(OR(LOWER(TRIM(CT12&""))="7 eller flere"),1,0) -> 0 | CV12: Under | CX12: Lamine Yamal | CZ12: 7–8 | DA12: =IF(OR(LOWER(TRIM(CZ12&""))="9+"),1,0) -> 0 | DB12: 3–4 | DD12: Norge | DE12: =IF(OR(LOWER(TRIM(DD12&""))="norge"),1,0) -> 1 | DF12: uavgjort | DG12: =IF(OR(LOWER(TRIM(DF12&""))="norge"),1,0) -> 0 | DH12: Frankrike | DI12: =IF(OR(LOWER(TRIM(DH12&""))="frankrike"),1,0) -> 1 | DJ12: 32 | DL12: Julian Ryerson | DM12: =IF(OR(LOWER(TRIM(DL12&""))="patrick berg"),1,0) -> 0 | DN12: Nei | DP12: Nei | DQ12: =IF(OR(LOWER(TRIM(DP12&""))="ja"),1,0) -> 0 | DR12: 33-35 | DS12: =IF(OR(LOWER(TRIM(DR12&""))="over 37"),1,0) -> 0 | DT12: 16. delsfinale | DV12: 0 | DX12: Nei | DY12: 1 | DZ12: 1 | EB12: Nei | ED12: Haaland | EE12: =IF(OR(LOWER(TRIM(ED12&""))="haaland"),1,0) -> 1 | EF12: 4 | EG12: =IF(OR(LOWER(TRIM(EF12&""))="5+"),1,0) -> 0 | EH12: 10435 meter
A13: 11 | B13: 46184.642 | C13: 46184.647 | D13: anonymous | F13: Mathias Berge | G13: =SUM(I13:EI13) -> 12 | I13: =IF(OR(LOWER(TRIM(H13&""))="7"),1,0) -> 0 | J13: 15+ | K13: =IF(OR(LOWER(TRIM(J13&""))="15+"),1,0) -> 1 | L13: New Zealand | M13: =IF(OR(LOWER(TRIM(L13&""))="ghana",LOWER(TRIM(L13&""))="annen"),1,0) -> 0 | N13: New Zealand | O13: =IF(OR(LOWER(TRIM(N13&""))="bosnia-hercegovina"),1,0) -> 0 | P13: Sveits | Q13: =IF(OR(LOWER(TRIM(P13&""))="tyrkia",LOWER(TRIM(P13&""))="tyrikia"),1,0) -> 0 | R13: 2 | S13: =IF(OR(LOWER(TRIM(R13&""))="2"),1,0) -> 1 | T13: 6+ | U13: =IF(OR(LOWER(TRIM(T13&""))="6+"),1,0) -> 1 | V13: Over 251 | W13: =IF(OR(LOWER(TRIM(V13&""))="201-250",LOWER(TRIM(V13&""))="215"),1,0) -> 0 | X13: 5 eller flere | Y13: =IF(OR(LOWER(TRIM(X13&""))="1",LOWER(TRIM(X13&""))="1 - panama"),1,0) -> 0 | Z13: Flere enn 2 | AA13: =IF(OR(LOWER(TRIM(Z13&""))="flere enn 2",LOWER(TRIM(Z13&""))="12"),1,0) -> 1 | AB13: 3 | AC13: =IF(OR(LOWER(TRIM(AB13&""))="4"),1,0) -> 0 | AD13: 3 | AE13: =IF(OR(LOWER(TRIM(AD13&""))="4"),1,0) -> 0 | AF13: 4 | AG13: =IF(OR(LOWER(TRIM(AF13&""))="3"),1,0) -> 0 | AH13: 0 | AI13: =IF(OR(LOWER(TRIM(AH13&""))="3"),1,0) -> 0 | AJ13: 1 | AK13: =IF(OR(LOWER(TRIM(AJ13&""))="1"),1,0) -> 1 | AL13: 0 | AM13: =IF(OR(LOWER(TRIM(AL13&""))="2"),1,0) -> 0 | AN13: USA | AP13: Spania | AR13: Marokko | AT13: Argentina | AV13: Japan | AW13: =IF(OR(LOWER(TRIM(AV13&""))="australia",LOWER(TRIM(AV13&""))="japan",LOWER(TRIM(AV13&""))="australia og japan"),1,0) -> 1 | AX13: 4 | AZ13: Ja | BB13: 0 | BD13: 4 | BF13: Ja | BH13: Ja | BJ13: Ja | BL13: Nei | BM13: =IF(OR(LOWER(TRIM(BL13&""))="nei"),1,0) -> 1 | BN13: Kylian Mbappé | BP13: Lamine Yamal | BR13: Emiliano Martínez | BT13: Lamine Yamal | BV13: Annen | BX13: Over 300 | BZ13: Spania | CB13: England | CD13: Spania | CF13: Messi | CH13: Nei | CJ13: 7 | CL13: 8 eller flere | CN13: Under 200 | CP13: 21-30 | CR13: 3 | CT13: 0-4 | CU13: =IF(OR(LOWER(TRIM(CT13&""))="7 eller flere"),1,0) -> 0 | CV13: Under | CX13: Lamine Yamal | CZ13: 9+ | DA13: =IF(OR(LOWER(TRIM(CZ13&""))="9+"),1,0) -> 1 | DB13: 7–8 | DD13: Norge | DE13: =IF(OR(LOWER(TRIM(DD13&""))="norge"),1,0) -> 1 | DF13: Norge | DG13: =IF(OR(LOWER(TRIM(DF13&""))="norge"),1,0) -> 1 | DH13: Frankrike | DI13: =IF(OR(LOWER(TRIM(DH13&""))="frankrike"),1,0) -> 1 | DJ13: Kvartfinale | DL13: Julian Ryerson | DM13: =IF(OR(LOWER(TRIM(DL13&""))="patrick berg"),1,0) -> 0 | DN13: Nei | DP13: Nei | DQ13: =IF(OR(LOWER(TRIM(DP13&""))="ja"),1,0) -> 0 | DR13: Under 33 | DS13: =IF(OR(LOWER(TRIM(DR13&""))="over 37"),1,0) -> 0 | DT13: Kvartfinale | DV13: 2 | DX13: Ja | DY13: 0 | DZ13: 2 | EB13: Nei | ED13: Haaland | EE13: =IF(OR(LOWER(TRIM(ED13&""))="haaland"),1,0) -> 1 | EF13: 4 | EG13: =IF(OR(LOWER(TRIM(EF13&""))="5+"),1,0) -> 0 | EH13: 14.2 km
A14: 12 | B14: 46184.806 | C14: 46184.81 | D14: anonymous | F14: Martin Moen | G14: =SUM(I14:EI14) -> 11 | H14: 7 | I14: =IF(OR(LOWER(TRIM(H14&""))="7"),1,0) -> 1 | J14: 7–9 | K14: =IF(OR(LOWER(TRIM(J14&""))="15+"),1,0) -> 0 | L14: Sør-Afrika | M14: =IF(OR(LOWER(TRIM(L14&""))="ghana",LOWER(TRIM(L14&""))="annen"),1,0) -> 0 | N14: Ghana | O14: =IF(OR(LOWER(TRIM(N14&""))="bosnia-hercegovina"),1,0) -> 0 | P14: Tyrkia | Q14: =IF(OR(LOWER(TRIM(P14&""))="tyrkia",LOWER(TRIM(P14&""))="tyrikia"),1,0) -> 1 | R14: 3 | S14: =IF(OR(LOWER(TRIM(R14&""))="2"),1,0) -> 0 | T14: 4 | U14: =IF(OR(LOWER(TRIM(T14&""))="6+"),1,0) -> 0 | V14: 101-150 | W14: =IF(OR(LOWER(TRIM(V14&""))="201-250",LOWER(TRIM(V14&""))="215"),1,0) -> 0 | X14: 3 | Y14: =IF(OR(LOWER(TRIM(X14&""))="1",LOWER(TRIM(X14&""))="1 - panama"),1,0) -> 0 | Z14: Flere enn 2 | AA14: =IF(OR(LOWER(TRIM(Z14&""))="flere enn 2",LOWER(TRIM(Z14&""))="12"),1,0) -> 1 | AB14: 0 | AC14: =IF(OR(LOWER(TRIM(AB14&""))="4"),1,0) -> 0 | AD14: 2 | AE14: =IF(OR(LOWER(TRIM(AD14&""))="4"),1,0) -> 0 | AF14: 1 | AG14: =IF(OR(LOWER(TRIM(AF14&""))="3"),1,0) -> 0 | AH14: 1 | AI14: =IF(OR(LOWER(TRIM(AH14&""))="3"),1,0) -> 0 | AJ14: 1 | AK14: =IF(OR(LOWER(TRIM(AJ14&""))="1"),1,0) -> 1 | AL14: 1 | AM14: =IF(OR(LOWER(TRIM(AL14&""))="2"),1,0) -> 0 | AN14: Mexico | AP14: Frankrike | AR14: Egypt | AT14: Argentina | AV14: Japan | AW14: =IF(OR(LOWER(TRIM(AV14&""))="australia",LOWER(TRIM(AV14&""))="japan",LOWER(TRIM(AV14&""))="australia og japan"),1,0) -> 1 | AX14: 4 | AZ14: Ja | BB14: 5 | BD14: Flere enn 5 | BF14: Ja | BH14: Ja | BJ14: Nei | BL14: Nei | BM14: =IF(OR(LOWER(TRIM(BL14&""))="nei"),1,0) -> 1 | BN14: Kylian Mbappé | BP14: Lionel Messi | BR14: Alisson Becker | BT14: Lamine Yamal | BV14: Granit Xhaka | BX14: 150-200 | BZ14: Spania | CB14: Frankrike | CD14: Spania | CF14: Messi | CH14: Ja | CJ14: 6 | CL14: 4-5 | CN14: Under 200 | CP14: 11-20 | CR14: 5 eller flere | CT14: 0-4 | CU14: =IF(OR(LOWER(TRIM(CT14&""))="7 eller flere"),1,0) -> 0 | CV14: Under | CX14: Lamine Yamal | CZ14: 5–6 | DA14: =IF(OR(LOWER(TRIM(CZ14&""))="9+"),1,0) -> 0 | DB14: 5–6 | DD14: Norge | DE14: =IF(OR(LOWER(TRIM(DD14&""))="norge"),1,0) -> 1 | DF14: uavgjort | DG14: =IF(OR(LOWER(TRIM(DF14&""))="norge"),1,0) -> 0 | DH14: Frankrike | DI14: =IF(OR(LOWER(TRIM(DH14&""))="frankrike"),1,0) -> 1 | DJ14: 8 dels | DL14: Fredrik Aursnes | DM14: =IF(OR(LOWER(TRIM(DL14&""))="patrick berg"),1,0) -> 0 | DN14: Nei | DP14: Ja | DQ14: =IF(OR(LOWER(TRIM(DP14&""))="ja"),1,0) -> 1 | DR14: 35-37 | DS14: =IF(OR(LOWER(TRIM(DR14&""))="over 37"),1,0) -> 0 | DT14: 8. delsfinale | DV14: 2 | DX14: Nei | DY14: 1 | DZ14: 1 | EB14: Nei | ED14: Haaland | EE14: =IF(OR(LOWER(TRIM(ED14&""))="haaland"),1,0) -> 1 | EF14: 2 | EG14: =IF(OR(LOWER(TRIM(EF14&""))="5+"),1,0) -> 0 | EH14: 14651m
A15: 13 | B15: 46184.811 | C15: 46184.819 | D15: anonymous | F15: Karsten | G15: =SUM(I15:EI15) -> 7 | H15: 6 | I15: =IF(OR(LOWER(TRIM(H15&""))="7"),1,0) -> 0 | J15: 7–9 | K15: =IF(OR(LOWER(TRIM(J15&""))="15+"),1,0) -> 0 | L15: Sør-Afrika | M15: =IF(OR(LOWER(TRIM(L15&""))="ghana",LOWER(TRIM(L15&""))="annen"),1,0) -> 0 | N15: Kapp Verde | O15: =IF(OR(LOWER(TRIM(N15&""))="bosnia-hercegovina"),1,0) -> 0 | P15: Tyskland | Q15: =IF(OR(LOWER(TRIM(P15&""))="tyrkia",LOWER(TRIM(P15&""))="tyrikia"),1,0) -> 0 | R15: 2 | S15: =IF(OR(LOWER(TRIM(R15&""))="2"),1,0) -> 1 | T15: 5 | U15: =IF(OR(LOWER(TRIM(T15&""))="6+"),1,0) -> 0 | V15: 151-200 | W15: =IF(OR(LOWER(TRIM(V15&""))="201-250",LOWER(TRIM(V15&""))="215"),1,0) -> 0 | X15: 2 | Y15: =IF(OR(LOWER(TRIM(X15&""))="1",LOWER(TRIM(X15&""))="1 - panama"),1,0) -> 0 | Z15: 1 | AA15: =IF(OR(LOWER(TRIM(Z15&""))="flere enn 2",LOWER(TRIM(Z15&""))="12"),1,0) -> 0 | AB15: 2 | AC15: =IF(OR(LOWER(TRIM(AB15&""))="4"),1,0) -> 0 | AD15: 2 | AE15: =IF(OR(LOWER(TRIM(AD15&""))="4"),1,0) -> 0 | AF15: 2 | AG15: =IF(OR(LOWER(TRIM(AF15&""))="3"),1,0) -> 0 | AH15: 2 | AI15: =IF(OR(LOWER(TRIM(AH15&""))="3"),1,0) -> 0 | AJ15: 3 | AK15: =IF(OR(LOWER(TRIM(AJ15&""))="1"),1,0) -> 0 | AL15: 1 | AM15: =IF(OR(LOWER(TRIM(AL15&""))="2"),1,0) -> 0 | AN15: Canada | AP15: Frankrike | AR15: Marokko | AT15: Argentina | AV15: Sør-Korea | AW15: =IF(OR(LOWER(TRIM(AV15&""))="australia",LOWER(TRIM(AV15&""))="japan",LOWER(TRIM(AV15&""))="australia og japan"),1,0) -> 0 | AX15: 4 | AZ15: Ja | BB15: 3 | BD15: Flere enn 5 | BF15: Ja | BH15: Ja | BJ15: Nei | BL15: Nei | BM15: =IF(OR(LOWER(TRIM(BL15&""))="nei"),1,0) -> 1 | BN15: Kylian Mbappé | BP15: Bruno Fernandes | BR15: Emiliano Martínez | BT15: Lamine Yamal | BV15: Virgil van Dijk | BX15: 201-250 | BZ15: Frankrike | CB15: Nederland | CD15: Argentina | CF15: Messi | CH15: Ja | CJ15: 7 | CL15: 0-3 | CN15: 201-299 | CP15: 21-30 | CR15: 4 | CT15: 0-4 | CU15: =IF(OR(LOWER(TRIM(CT15&""))="7 eller flere"),1,0) -> 0 | CV15: Under | CX15: Lamine Yamal | CZ15: 7–8 | DA15: =IF(OR(LOWER(TRIM(CZ15&""))="9+"),1,0) -> 0 | DB15: 5–6 | DD15: Norge | DE15: =IF(OR(LOWER(TRIM(DD15&""))="norge"),1,0) -> 1 | DF15: Norge | DG15: =IF(OR(LOWER(TRIM(DF15&""))="norge"),1,0) -> 1 | DH15: Frankrike | DI15: =IF(OR(LOWER(TRIM(DH15&""))="frankrike"),1,0) -> 1 | DJ15: 8. delsfinale | DL15: Julian Ryerson | DM15: =IF(OR(LOWER(TRIM(DL15&""))="patrick berg"),1,0) -> 0 | DN15: Nei | DP15: Ja | DQ15: =IF(OR(LOWER(TRIM(DP15&""))="ja"),1,0) -> 1 | DR15: 33-35 | DS15: =IF(OR(LOWER(TRIM(DR15&""))="over 37"),1,0) -> 0 | DT15: 8. delsfinale | DV15: 2 | DX15: Nei | DY15: 1 | DZ15: 1 | EB15: Ja | ED15: Bobb | EE15: =IF(OR(LOWER(TRIM(ED15&""))="haaland"),1,0) -> 0 | EF15: 3 | EG15: =IF(OR(LOWER(TRIM(EF15&""))="5+"),1,0) -> 0
A16: 14 | B16: 46184.817 | C16: 46184.822 | D16: anonymous | F16: Zippo | G16: =SUM(I16:EI16) -> 8 | H16: Under 5 | I16: =IF(OR(LOWER(TRIM(H16&""))="7"),1,0) -> 0 | J16: 0–6 | K16: =IF(OR(LOWER(TRIM(J16&""))="15+"),1,0) -> 0 | L16: Sør-Afrika | M16: =IF(OR(LOWER(TRIM(L16&""))="ghana",LOWER(TRIM(L16&""))="annen"),1,0) -> 0 | N16: Bosnia-Hercegovina | O16: =IF(OR(LOWER(TRIM(N16&""))="bosnia-hercegovina"),1,0) -> 1 | P16: Belgia | Q16: =IF(OR(LOWER(TRIM(P16&""))="tyrkia",LOWER(TRIM(P16&""))="tyrikia"),1,0) -> 0 | R16: 1 | S16: =IF(OR(LOWER(TRIM(R16&""))="2"),1,0) -> 0 | T16: 6+ | U16: =IF(OR(LOWER(TRIM(T16&""))="6+"),1,0) -> 1 | V16: 101-150 | W16: =IF(OR(LOWER(TRIM(V16&""))="201-250",LOWER(TRIM(V16&""))="215"),1,0) -> 0 | X16: 4 | Y16: =IF(OR(LOWER(TRIM(X16&""))="1",LOWER(TRIM(X16&""))="1 - panama"),1,0) -> 0 | Z16: Flere enn 2 | AA16: =IF(OR(LOWER(TRIM(Z16&""))="flere enn 2",LOWER(TRIM(Z16&""))="12"),1,0) -> 1 | AB16: 2 | AC16: =IF(OR(LOWER(TRIM(AB16&""))="4"),1,0) -> 0 | AD16: 3 | AE16: =IF(OR(LOWER(TRIM(AD16&""))="4"),1,0) -> 0 | AF16: 2 | AG16: =IF(OR(LOWER(TRIM(AF16&""))="3"),1,0) -> 0 | AH16: 1 | AI16: =IF(OR(LOWER(TRIM(AH16&""))="3"),1,0) -> 0 | AJ16: 0 | AK16: =IF(OR(LOWER(TRIM(AJ16&""))="1"),1,0) -> 0 | AL16: 0 | AM16: =IF(OR(LOWER(TRIM(AL16&""))="2"),1,0) -> 0 | AN16: Mexico | AP16: Frankrike | AR16: Marokko | AT16: Ecuador | AV16: Japan | AW16: =IF(OR(LOWER(TRIM(AV16&""))="australia",LOWER(TRIM(AV16&""))="japan",LOWER(TRIM(AV16&""))="australia og japan"),1,0) -> 1 | AX16: 4 | AZ16: Ja | BB16: 2 | BD16: 4 | BF16: Ja | BH16: Ja | BJ16: Ja | BL16: Nei | BM16: =IF(OR(LOWER(TRIM(BL16&""))="nei"),1,0) -> 1 | BN16: Kylian Mbappé | BP16: Bruno Fernandes | BR16: Unai Simón | BT16: Lamine Yamal | BV16: João Palhinha | BX16: 201-250 | BZ16: Spania | CB16: England | CD16: Frankrike | CF16: Messi | CH16: Nei | CJ16: 5 | CL16: 0-3 | CN16: 201-299 | CP16: 11-20 | CR16: 3 | CT16: 0-4 | CU16: =IF(OR(LOWER(TRIM(CT16&""))="7 eller flere"),1,0) -> 0 | CV16: Under | CX16: Lamine Yamal | CZ16: 5–6 | DA16: =IF(OR(LOWER(TRIM(CZ16&""))="9+"),1,0) -> 0 | DB16: 3–4 | DD16: Norge | DE16: =IF(OR(LOWER(TRIM(DD16&""))="norge"),1,0) -> 1 | DF16: Norge | DG16: =IF(OR(LOWER(TRIM(DF16&""))="norge"),1,0) -> 1 | DH16: Norge | DI16: =IF(OR(LOWER(TRIM(DH16&""))="frankrike"),1,0) -> 0 | DJ16: 10 | DL16: David Møller Wolfe | DM16: =IF(OR(LOWER(TRIM(DL16&""))="patrick berg"),1,0) -> 0 | DN16: Nei | DP16: Ja | DQ16: =IF(OR(LOWER(TRIM(DP16&""))="ja"),1,0) -> 1 | DR16: 33-35 | DS16: =IF(OR(LOWER(TRIM(DR16&""))="over 37"),1,0) -> 0 | DT16: 8. delsfinale | DV16: 2 | DX16: Ja | DY16: 0 | DZ16: 1 | EB16: Ja | ED16: Sørloth | EE16: =IF(OR(LOWER(TRIM(ED16&""))="haaland"),1,0) -> 0 | EF16: 4 | EG16: =IF(OR(LOWER(TRIM(EF16&""))="5+"),1,0) -> 0 | EH16: 13 km
A17: 15 | B17: 46184.842 | C17: 46184.85 | D17: anonymous | F17: Robin | G17: =SUM(I17:EI17) -> 11 | H17: Under 5 | I17: =IF(OR(LOWER(TRIM(H17&""))="7"),1,0) -> 0 | J17: 0–6 | K17: =IF(OR(LOWER(TRIM(J17&""))="15+"),1,0) -> 0 | L17: New Zealand | M17: =IF(OR(LOWER(TRIM(L17&""))="ghana",LOWER(TRIM(L17&""))="annen"),1,0) -> 0 | N17: Bosnia-Hercegovina | O17: =IF(OR(LOWER(TRIM(N17&""))="bosnia-hercegovina"),1,0) -> 1 | P17: Østerrike | Q17: =IF(OR(LOWER(TRIM(P17&""))="tyrkia",LOWER(TRIM(P17&""))="tyrikia"),1,0) -> 0 | R17: 2 | S17: =IF(OR(LOWER(TRIM(R17&""))="2"),1,0) -> 1 | T17: 5 | U17: =IF(OR(LOWER(TRIM(T17&""))="6+"),1,0) -> 0 | V17: 101-150 | W17: =IF(OR(LOWER(TRIM(V17&""))="201-250",LOWER(TRIM(V17&""))="215"),1,0) -> 0 | X17: 2 | Y17: =IF(OR(LOWER(TRIM(X17&""))="1",LOWER(TRIM(X17&""))="1 - panama"),1,0) -> 0 | Z17: 2 | AA17: =IF(OR(LOWER(TRIM(Z17&""))="flere enn 2",LOWER(TRIM(Z17&""))="12"),1,0) -> 0 | AB17: 1 | AC17: =IF(OR(LOWER(TRIM(AB17&""))="4"),1,0) -> 0 | AD17: 2 | AE17: =IF(OR(LOWER(TRIM(AD17&""))="4"),1,0) -> 0 | AF17: 3 | AG17: =IF(OR(LOWER(TRIM(AF17&""))="3"),1,0) -> 1 | AH17: 1 | AI17: =IF(OR(LOWER(TRIM(AH17&""))="3"),1,0) -> 0 | AJ17: 1 | AK17: =IF(OR(LOWER(TRIM(AJ17&""))="1"),1,0) -> 1 | AL17: 1 | AM17: =IF(OR(LOWER(TRIM(AL17&""))="2"),1,0) -> 0 | AN17: Canada | AP17: Frankrike | AR17: Marokko | AT17: Argentina | AV17: Sør-Korea | AW17: =IF(OR(LOWER(TRIM(AV17&""))="australia",LOWER(TRIM(AV17&""))="japan",LOWER(TRIM(AV17&""))="australia og japan"),1,0) -> 0 | AX17: 1-3 | AZ17: Ja | BB17: 2 | BD17: 2 | BF17: Ja | BH17: Ja | BJ17: Ja | BL17: Nei | BM17: =IF(OR(LOWER(TRIM(BL17&""))="nei"),1,0) -> 1 | BN17: Annen | BP17: Bruno Fernandes | BR17: Unai Simón | BT17: Lamine Yamal | BV17: Rodrigo De Paul | BX17: 251-300 | BZ17: Spania | CB17: England | CD17: Portugal | CF17: Messi | CH17: Nei | CJ17: 9 | CL17: 4-5 | CN17: Under 200 | CP17: 11-20 | CR17: 3 | CT17: 0-4 | CU17: =IF(OR(LOWER(TRIM(CT17&""))="7 eller flere"),1,0) -> 0 | CV17: Under | CX17: Lamine Yamal | CZ17: 9+ | DA17: =IF(OR(LOWER(TRIM(CZ17&""))="9+"),1,0) -> 1 | DB17: 5–6 | DD17: Norge | DE17: =IF(OR(LOWER(TRIM(DD17&""))="norge"),1,0) -> 1 | DF17: Norge | DG17: =IF(OR(LOWER(TRIM(DF17&""))="norge"),1,0) -> 1 | DH17: Frankrike | DI17: =IF(OR(LOWER(TRIM(DH17&""))="frankrike"),1,0) -> 1 | DJ17: 7 | DL17: Julian Ryerson | DM17: =IF(OR(LOWER(TRIM(DL17&""))="patrick berg"),1,0) -> 0 | DN17: Nei | DP17: Nei | DQ17: =IF(OR(LOWER(TRIM(DP17&""))="ja"),1,0) -> 0 | DR17: 33-35 | DS17: =IF(OR(LOWER(TRIM(DR17&""))="over 37"),1,0) -> 0 | DT17: Kvartfinale | DV17: Flere enn 2 | DX17: Ja | DY17: 0 | DZ17: 2 | EB17: Nei | ED17: Haaland | EE17: =IF(OR(LOWER(TRIM(ED17&""))="haaland"),1,0) -> 1 | EF17: 5+ | EG17: =IF(OR(LOWER(TRIM(EF17&""))="5+"),1,0) -> 1 | EH17: 3,8km
A18: 16 | B18: 46184.848 | C18: 46184.859 | D18: anonymous | F18: Arvin Conradi | G18: =SUM(I18:EI18) -> 14 | H18: 6 | I18: =IF(OR(LOWER(TRIM(H18&""))="7"),1,0) -> 0 | J18: 7–9 | K18: =IF(OR(LOWER(TRIM(J18&""))="15+"),1,0) -> 0 | L18: New Zealand | M18: =IF(OR(LOWER(TRIM(L18&""))="ghana",LOWER(TRIM(L18&""))="annen"),1,0) -> 0 | N18: Paraguay | O18: =IF(OR(LOWER(TRIM(N18&""))="bosnia-hercegovina"),1,0) -> 0 | P18: Østerrike | Q18: =IF(OR(LOWER(TRIM(P18&""))="tyrkia",LOWER(TRIM(P18&""))="tyrikia"),1,0) -> 0 | R18: 2 | S18: =IF(OR(LOWER(TRIM(R18&""))="2"),1,0) -> 1 | T18: 4 | U18: =IF(OR(LOWER(TRIM(T18&""))="6+"),1,0) -> 0 | V18: 201-250 | W18: =IF(OR(LOWER(TRIM(V18&""))="201-250",LOWER(TRIM(V18&""))="215"),1,0) -> 1 | X18: 2 | Y18: =IF(OR(LOWER(TRIM(X18&""))="1",LOWER(TRIM(X18&""))="1 - panama"),1,0) -> 0 | Z18: Flere enn 2 | AA18: =IF(OR(LOWER(TRIM(Z18&""))="flere enn 2",LOWER(TRIM(Z18&""))="12"),1,0) -> 1 | AB18: 3 | AC18: =IF(OR(LOWER(TRIM(AB18&""))="4"),1,0) -> 0 | AD18: 4 | AE18: =IF(OR(LOWER(TRIM(AD18&""))="4"),1,0) -> 1 | AF18: 4 | AG18: =IF(OR(LOWER(TRIM(AF18&""))="3"),1,0) -> 0 | AH18: 2 | AI18: =IF(OR(LOWER(TRIM(AH18&""))="3"),1,0) -> 0 | AJ18: 1 | AK18: =IF(OR(LOWER(TRIM(AJ18&""))="1"),1,0) -> 1 | AL18: 2 | AM18: =IF(OR(LOWER(TRIM(AL18&""))="2"),1,0) -> 1 | AN18: Mexico | AP18: Spania | AR18: Marokko | AT18: Argentina | AV18: Japan | AW18: =IF(OR(LOWER(TRIM(AV18&""))="australia",LOWER(TRIM(AV18&""))="japan",LOWER(TRIM(AV18&""))="australia og japan"),1,0) -> 1 | AX18: 6+ | AZ18: Ja | BB18: 3 | BD18: Flere enn 5 | BF18: Ja | BH18: Nei | BJ18: Ja | BL18: Nei | BM18: =IF(OR(LOWER(TRIM(BL18&""))="nei"),1,0) -> 1 | BN18: Harry Kane | BP18: Lionel Messi | BR18: Diogo Costa | BT18: Lamine Yamal | BV18: Annen | BX18: 251-300 | BZ18: Spania | CB18: Nederland | CD18: Spania | CF18: Messi | CH18: Ja | CJ18: 7 | CL18: 8 eller flere | CN18: 300 eller flere | CP18: 11-20 | CR18: 5 eller flere | CT18: 7 eller flere | CU18: =IF(OR(LOWER(TRIM(CT18&""))="7 eller flere"),1,0) -> 1 | CV18: Under | CX18: Lamine Yamal | CZ18: 9+ | DA18: =IF(OR(LOWER(TRIM(CZ18&""))="9+"),1,0) -> 1 | DB18: 7–8 | DD18: Norge | DE18: =IF(OR(LOWER(TRIM(DD18&""))="norge"),1,0) -> 1 | DF18: uavgjort | DG18: =IF(OR(LOWER(TRIM(DF18&""))="norge"),1,0) -> 0 | DH18: Frankrike | DI18: =IF(OR(LOWER(TRIM(DH18&""))="frankrike"),1,0) -> 1 | DJ18: Åtendelsfinale | DL18: Julian Ryerson | DM18: =IF(OR(LOWER(TRIM(DL18&""))="patrick berg"),1,0) -> 0 | DN18: Nei | DP18: Ja | DQ18: =IF(OR(LOWER(TRIM(DP18&""))="ja"),1,0) -> 1 | DR18: Over 37 | DS18: =IF(OR(LOWER(TRIM(DR18&""))="over 37"),1,0) -> 1 | DT18: 8. delsfinale | DV18: Flere enn 2 | DX18: Ja | DY18: 0 | DZ18: 2 | EB18: Nei | ED18: Sørloth | EE18: =IF(OR(LOWER(TRIM(ED18&""))="haaland"),1,0) -> 0 | EF18: 4 | EG18: =IF(OR(LOWER(TRIM(EF18&""))="5+"),1,0) -> 0 | EH18: 13 km
A19: 17 | B19: 46184.866 | C19: 46184.871 | D19: anonymous | F19: Julie | G19: =SUM(I19:EI19) -> 10 | H19: 8 | I19: =IF(OR(LOWER(TRIM(H19&""))="7"),1,0) -> 0 | J19: 7–9 | K19: =IF(OR(LOWER(TRIM(J19&""))="15+"),1,0) -> 0 | L19: Sør-Afrika | M19: =IF(OR(LOWER(TRIM(L19&""))="ghana",LOWER(TRIM(L19&""))="annen"),1,0) -> 0 | N19: Jordan | O19: =IF(OR(LOWER(TRIM(N19&""))="bosnia-hercegovina"),1,0) -> 0 | P19: Østerrike | Q19: =IF(OR(LOWER(TRIM(P19&""))="tyrkia",LOWER(TRIM(P19&""))="tyrikia"),1,0) -> 0 | R19: 3 | S19: =IF(OR(LOWER(TRIM(R19&""))="2"),1,0) -> 0 | T19: 4 | U19: =IF(OR(LOWER(TRIM(T19&""))="6+"),1,0) -> 0 | V19: 101-150 | W19: =IF(OR(LOWER(TRIM(V19&""))="201-250",LOWER(TRIM(V19&""))="215"),1,0) -> 0 | X19: 1 | Y19: =IF(OR(LOWER(TRIM(X19&""))="1",LOWER(TRIM(X19&""))="1 - panama"),1,0) -> 1 | Z19: 2 | AA19: =IF(OR(LOWER(TRIM(Z19&""))="flere enn 2",LOWER(TRIM(Z19&""))="12"),1,0) -> 0 | AB19: 2 | AC19: =IF(OR(LOWER(TRIM(AB19&""))="4"),1,0) -> 0 | AD19: 2 | AE19: =IF(OR(LOWER(TRIM(AD19&""))="4"),1,0) -> 0 | AF19: 3 | AG19: =IF(OR(LOWER(TRIM(AF19&""))="3"),1,0) -> 1 | AH19: 2 | AI19: =IF(OR(LOWER(TRIM(AH19&""))="3"),1,0) -> 0 | AJ19: 1 | AK19: =IF(OR(LOWER(TRIM(AJ19&""))="1"),1,0) -> 1 | AL19: 0 | AM19: =IF(OR(LOWER(TRIM(AL19&""))="2"),1,0) -> 0 | AN19: Mexico | AP19: Frankrike | AT19: Brasil | AV19: Australia | AW19: =IF(OR(LOWER(TRIM(AV19&""))="australia",LOWER(TRIM(AV19&""))="japan",LOWER(TRIM(AV19&""))="australia og japan"),1,0) -> 1 | AX19: 4 | AZ19: Ja | BB19: 3 | BD19: 3 | BF19: Ja | BH19: Ja | BJ19: Ja | BL19: Nei | BM19: =IF(OR(LOWER(TRIM(BL19&""))="nei"),1,0) -> 1 | BN19: Lionel Messi | BP19: Kevin De Bruyne | BR19: Alisson Becker | BT19: Endrick | BV19: Cristian Romero | BX19: 201-250 | BZ19: Frankrike | CB19: Portugal | CD19: Frankrike | CF19: Messi | CH19: Ja | CJ19: 9 | CL19: 4-5 | CN19: Under 200 | CP19: 0-10 | CR19: 3 | CT19: 0-4 | CU19: =IF(OR(LOWER(TRIM(CT19&""))="7 eller flere"),1,0) -> 0 | CV19: Under | CX19: Lamine Yamal | CZ19: 9+ | DA19: =IF(OR(LOWER(TRIM(CZ19&""))="9+"),1,0) -> 1 | DB19: 5–6 | DD19: Norge | DE19: =IF(OR(LOWER(TRIM(DD19&""))="norge"),1,0) -> 1 | DF19: Norge | DG19: =IF(OR(LOWER(TRIM(DF19&""))="norge"),1,0) -> 1 | DH19: Frankrike | DI19: =IF(OR(LOWER(TRIM(DH19&""))="frankrike"),1,0) -> 1 | DJ19: 7 | DL19: Julian Ryerson | DM19: =IF(OR(LOWER(TRIM(DL19&""))="patrick berg"),1,0) -> 0 | DN19: Nei | DP19: Ja | DQ19: =IF(OR(LOWER(TRIM(DP19&""))="ja"),1,0) -> 1 | DR19: 35-37 | DS19: =IF(OR(LOWER(TRIM(DR19&""))="over 37"),1,0) -> 0 | DT19: Kvartfinale | DV19: 2 | DX19: Ja | DY19: 0 | DZ19: 2 | EB19: Ja | ED19: Nusa | EE19: =IF(OR(LOWER(TRIM(ED19&""))="haaland"),1,0) -> 0 | EF19: 4 | EG19: =IF(OR(LOWER(TRIM(EF19&""))="5+"),1,0) -> 0 | EH19: 6700
A20: 18 | B20: 46184.864 | C20: 46184.872 | D20: anonymous | F20: Adrian | G20: =SUM(I20:EI20) -> 9 | H20: 6 | I20: =IF(OR(LOWER(TRIM(H20&""))="7"),1,0) -> 0 | J20: 7–9 | K20: =IF(OR(LOWER(TRIM(J20&""))="15+"),1,0) -> 0 | L20: Sør-Afrika | M20: =IF(OR(LOWER(TRIM(L20&""))="ghana",LOWER(TRIM(L20&""))="annen"),1,0) -> 0 | N20: New Zealand | O20: =IF(OR(LOWER(TRIM(N20&""))="bosnia-hercegovina"),1,0) -> 0 | P20: Sveits | Q20: =IF(OR(LOWER(TRIM(P20&""))="tyrkia",LOWER(TRIM(P20&""))="tyrikia"),1,0) -> 0 | R20: 2 | S20: =IF(OR(LOWER(TRIM(R20&""))="2"),1,0) -> 1 | T20: 5 | U20: =IF(OR(LOWER(TRIM(T20&""))="6+"),1,0) -> 0 | V20: 151-200 | W20: =IF(OR(LOWER(TRIM(V20&""))="201-250",LOWER(TRIM(V20&""))="215"),1,0) -> 0 | X20: 2 | Y20: =IF(OR(LOWER(TRIM(X20&""))="1",LOWER(TRIM(X20&""))="1 - panama"),1,0) -> 0 | Z20: 2 | AA20: =IF(OR(LOWER(TRIM(Z20&""))="flere enn 2",LOWER(TRIM(Z20&""))="12"),1,0) -> 0 | AB20: 1 | AC20: =IF(OR(LOWER(TRIM(AB20&""))="4"),1,0) -> 0 | AD20: 2 | AE20: =IF(OR(LOWER(TRIM(AD20&""))="4"),1,0) -> 0 | AF20: 2 | AG20: =IF(OR(LOWER(TRIM(AF20&""))="3"),1,0) -> 0 | AH20: 2 | AI20: =IF(OR(LOWER(TRIM(AH20&""))="3"),1,0) -> 0 | AJ20: 2 | AK20: =IF(OR(LOWER(TRIM(AJ20&""))="1"),1,0) -> 0 | AL20: 1 | AM20: =IF(OR(LOWER(TRIM(AL20&""))="2"),1,0) -> 0 | AN20: USA | AP20: Spania | AR20: Egypt | AT20: Argentina | AV20: Japan | AW20: =IF(OR(LOWER(TRIM(AV20&""))="australia",LOWER(TRIM(AV20&""))="japan",LOWER(TRIM(AV20&""))="australia og japan"),1,0) -> 1 | AX20: 4 | AZ20: Nei | BB20: 2 | BD20: 2 | BF20: Ja | BH20: Ja | BJ20: Nei | BL20: Nei | BM20: =IF(OR(LOWER(TRIM(BL20&""))="nei"),1,0) -> 1 | BN20: Erling Haaland | BP20: Lamine Yamal | BR20: Emiliano Martínez | BT20: Lamine Yamal | BV20: Cristian Romero | BX20: 201-250 | BZ20: Norge | CB20: Spania | CD20: Annet lag | CF20: Messi | CH20: Ja | CJ20: Over 10 | CL20: 0-3 | CN20: Under 200 | CP20: 0-10 | CR20: 3 | CT20: 0-4 | CU20: =IF(OR(LOWER(TRIM(CT20&""))="7 eller flere"),1,0) -> 0 | CV20: Under | CX20: Lamine Yamal | CZ20: 7–8 | DA20: =IF(OR(LOWER(TRIM(CZ20&""))="9+"),1,0) -> 0 | DB20: 5–6 | DD20: Norge | DE20: =IF(OR(LOWER(TRIM(DD20&""))="norge"),1,0) -> 1 | DF20: Norge | DG20: =IF(OR(LOWER(TRIM(DF20&""))="norge"),1,0) -> 1 | DH20: uavgjort | DI20: =IF(OR(LOWER(TRIM(DH20&""))="frankrike"),1,0) -> 0 | DJ20: 1 | DL20: Kristoffer Ajer | DM20: =IF(OR(LOWER(TRIM(DL20&""))="patrick berg"),1,0) -> 0 | DN20: Nei | DP20: Ja | DQ20: =IF(OR(LOWER(TRIM(DP20&""))="ja"),1,0) -> 1 | DR20: Over 37 | DS20: =IF(OR(LOWER(TRIM(DR20&""))="over 37"),1,0) -> 1 | DT20: Finale | DV20: 1 | DX20: Nei | DY20: 1 | DZ20: 3 | EB20: Nei | ED20: Nusa | EE20: =IF(OR(LOWER(TRIM(ED20&""))="haaland"),1,0) -> 0 | EF20: 5+ | EG20: =IF(OR(LOWER(TRIM(EF20&""))="5+"),1,0) -> 1 | EH20: 16
A21: 19 | B21: 46184.93 | C21: 46184.934 | D21: anonymous | F21: ElToro | G21: =SUM(I21:EI21) -> 9 | H21: Under 5 | I21: =IF(OR(LOWER(TRIM(H21&""))="7"),1,0) -> 0 | J21: 10–12 | K21: =IF(OR(LOWER(TRIM(J21&""))="15+"),1,0) -> 0 | L21: Annen | M21: =IF(OR(LOWER(TRIM(L21&""))="ghana",LOWER(TRIM(L21&""))="annen"),1,0) -> 1 | N21: Bosnia-Hercegovina | O21: =IF(OR(LOWER(TRIM(N21&""))="bosnia-hercegovina"),1,0) -> 1 | P21: Annen | Q21: =IF(OR(LOWER(TRIM(P21&""))="tyrkia",LOWER(TRIM(P21&""))="tyrikia"),1,0) -> 0 | R21: 2 | S21: =IF(OR(LOWER(TRIM(R21&""))="2"),1,0) -> 1 | T21: 2-3 | U21: =IF(OR(LOWER(TRIM(T21&""))="6+"),1,0) -> 0 | V21: 201-250 | W21: =IF(OR(LOWER(TRIM(V21&""))="201-250",LOWER(TRIM(V21&""))="215"),1,0) -> 1 | X21: 2 | Y21: =IF(OR(LOWER(TRIM(X21&""))="1",LOWER(TRIM(X21&""))="1 - panama"),1,0) -> 0 | Z21: 2 | AA21: =IF(OR(LOWER(TRIM(Z21&""))="flere enn 2",LOWER(TRIM(Z21&""))="12"),1,0) -> 0 | AB21: 3 | AC21: =IF(OR(LOWER(TRIM(AB21&""))="4"),1,0) -> 0 | AD21: 3 | AE21: =IF(OR(LOWER(TRIM(AD21&""))="4"),1,0) -> 0 | AF21: 3 | AG21: =IF(OR(LOWER(TRIM(AF21&""))="3"),1,0) -> 1 | AH21: 1 | AI21: =IF(OR(LOWER(TRIM(AH21&""))="3"),1,0) -> 0 | AJ21: 0 | AK21: =IF(OR(LOWER(TRIM(AJ21&""))="1"),1,0) -> 0 | AL21: 1 | AM21: =IF(OR(LOWER(TRIM(AL21&""))="2"),1,0) -> 0 | AN21: Mexico | AP21: Spania | AR21: Senegal | AT21: Argentina | AV21: Japan | AW21: =IF(OR(LOWER(TRIM(AV21&""))="australia",LOWER(TRIM(AV21&""))="japan",LOWER(TRIM(AV21&""))="australia og japan"),1,0) -> 1 | AX21: 1-3 | AZ21: Nei | BB21: 0 | BD21: 3 | BF21: Ja | BH21: Ja | BJ21: Nei | BL21: Ja | BM21: =IF(OR(LOWER(TRIM(BL21&""))="nei"),1,0) -> 0 | BN21: Kylian Mbappé | BP21: Annen | BR21: Emiliano Martínez | BT21: Lamine Yamal | BV21: Annen | BX21: 251-300 | BZ21: Spania | CB21: Frankrike | CD21: Spania | CF21: Messi | CH21: Nei | CJ21: Over 10 | CL21: 4-5 | CN21: 201-299 | CP21: 21-30 | CR21: 2 | CT21: 0-4 | CU21: =IF(OR(LOWER(TRIM(CT21&""))="7 eller flere"),1,0) -> 0 | CX21: Lamine Yamal | CZ21: 3–4 | DA21: =IF(OR(LOWER(TRIM(CZ21&""))="9+"),1,0) -> 0 | DB21: 5–6 | DD21: Norge | DE21: =IF(OR(LOWER(TRIM(DD21&""))="norge"),1,0) -> 1 | DF21: uavgjort | DG21: =IF(OR(LOWER(TRIM(DF21&""))="norge"),1,0) -> 0 | DH21: Frankrike | DI21: =IF(OR(LOWER(TRIM(DH21&""))="frankrike"),1,0) -> 1 | DJ21: Kvart | DL21: Kristoffer Ajer | DM21: =IF(OR(LOWER(TRIM(DL21&""))="patrick berg"),1,0) -> 0 | DN21: Nei | DP21: Nei | DQ21: =IF(OR(LOWER(TRIM(DP21&""))="ja"),1,0) -> 0 | DR21: Over 37 | DS21: =IF(OR(LOWER(TRIM(DR21&""))="over 37"),1,0) -> 1 | DT21: 8. delsfinale | DV21: 1 | DX21: Ja | DY21: 0 | DZ21: 1 | EB21: Nei | ED21: Nusa | EE21: =IF(OR(LOWER(TRIM(ED21&""))="haaland"),1,0) -> 0 | EF21: 2 | EG21: =IF(OR(LOWER(TRIM(EF21&""))="5+"),1,0) -> 0 | EH21: 12

Sheet Original
A1: FASIT | G1: 7 | H1: 16 | I1: Ghana | J1: Bosnia-Hercegovina | K1: Tyrikia | L1: 2 | M1: 6 | N1: 215 | O1: 1 - Panama | P1: 12 | Q1: 4 | R1: 4 | S1: 3 | T1: 3 | U1: 1 | V1: 2 | AA1: Australia og Japan | AI1: Nei | AZ1: 7 eller flere | BC1: 9+ | BE1: Norge | BF1: Norge | BG1: Frankrike | BI1: Patrick Berg | BK1: Ja | BL1: Over 37 | BR1: Haaland | BS1: 5+
